<robot name="mobile_robot" xmlns:xacro="http://www.ros.org/wiki/xacro">
<xacro:include filename="$(find my_robot)/urdf/mobile_robot.gazebo" />

  <link name="robot_footprint"></link>

  <joint name="robot_footprint_joint" type="fixed">
    <origin xyz="0 0 0" rpy="0 0 0" />
    <parent link="robot_footprint"/>
    <child link="chassis" />
  </joint>


  <!-- chassis -->
  <link name='chassis'>
    <pose>0 0 0.1 0 0 0</pose>

    <inertial>
      <mass value="10.0"/>
      <origin xyz="0.0 0 0" rpy=" 0 0 0"/>
      <inertia
          ixx="0.1" ixy="0" ixz="0"
          iyy="0.1" iyz="0"
          izz="0.1"
      />
    </inertial>

    <collision name='chassis_collision'>
      <origin xyz="0 0 0" rpy=" 0 0 0"/> 
      <geometry>
        <box size=".35 .15 .08"/>
      </geometry>
    </collision>

    <visual name='chassis_visual'>
      <origin xyz="0 0 0" rpy=" 0 0 0"/>
      <geometry>
        <box size=".35 .15 .08"/>
      </geometry>
    </visual>
    
    <!-- front_caster_collision -->
    <collision name='front_caster_collision'>
      <origin xyz="0.10 0 -0.04" rpy=" 0 0 0"/>
      <geometry>
        <sphere radius="0.04"/>
      </geometry>
    </collision>

    <visual name='front_caster_visual'>
      <origin xyz="0.10 0 -0.04" rpy=" 0 0 0"/>
      <geometry>
        <sphere radius="0.04"/>
      </geometry>
    </visual>
  </link>

  <!-- chassis_back -->
  <link name='chassis_back'>
    <inertial>
      <mass value="5.0"/>
      <origin xyz="0.0 0 0" rpy=" 0 0 0"/>
      <inertia
          ixx="0.1" ixy="0" ixz="0"
          iyy="0.1" iyz="0"
          izz="0.1"
      />
    </inertial>

    <collision name='chassis_back_collision'>
      <origin xyz="0 0 0" rpy=" 0 0 0"/> 
      <geometry>
        <box size=".18 .15 .08"/>
      </geometry>
    </collision>

    <visual name='chassis_back_visual'>
      <origin xyz="0 0 0" rpy=" 0 0 0"/>
      <geometry>
        <box size=".18 .15 .08"/>
      </geometry>
    </visual>
    </link>

   <joint type="fixed" name="chassis_back_joint">
    <origin xyz="-0.1 0 0.06" rpy="0 0 0"/>
    <child link="chassis_back"/>
    <parent link="chassis"/>
    <axis xyz="0 1 0" rpy="0 0 0"/>
  </joint>

  <!-- left_wheel -->
   <link name='left_wheel'>
    <inertial>
      <mass value="2.5"/>
      <origin xyz="0 0 0" rpy=" 0 1.5707 1.5707"/>
      <inertia
        ixx="0.1" ixy="0" ixz="0"
        iyy="0.1" iyz="0"
        izz="0.1"
      />
    </inertial>

  <collision name='left_wheel_collision'>
    <origin xyz="0 0 0" rpy=" 0 1.5707 1.5707"/> 
      <geometry>
        <cylinder radius=".08" length="0.025"/>
      </geometry>
  </collision>

  <visual name='left_wheel_visual'>
    <origin xyz="0 0 0" rpy=" 0 1.5707 1.5707"/>
    <geometry>
      <cylinder radius=".08" length="0.025"/>
    </geometry>
  </visual>
  </link>

  <joint type="continuous" name="left_wheel_hinge">
    <origin xyz="-0.085 0.1 0" rpy="0 0 0"/>
    <child link="left_wheel"/>
    <parent link="chassis"/>
    <axis xyz="0 1 0" rpy="0 0 0"/>
    <limit effort="10000" velocity="1000"/>
    <dynamics damping="1.0" friction="1.0"/>
  </joint>

  <!-- right_wheel -->
  <link name='right_wheel'>
    <inertial>
    <mass value="2.5"/>
    <origin xyz="0 0 0" rpy=" 0 1.5707 1.5707"/>
    <inertia
        ixx="0.1" ixy="0" ixz="0"
        iyy="0.1" iyz="0"
        izz="0.1"
    />
  </inertial>

  <collision name='right_wheel_collision'>
    <origin xyz="0 0 0" rpy=" 0 1.5707 1.5707"/> 
    <geometry>
      <cylinder radius=".08" length="0.025"/>
    </geometry>
  </collision>

  <visual name='right_wheel_visual'>
    <origin xyz="0 0 0" rpy=" 0 1.5707 1.5707"/>
    <geometry>
      <cylinder radius=".08" length="0.025"/>
    </geometry>
  </visual>
  </link>

  <joint type="continuous" name="right_wheel_hinge">
    <origin xyz="-0.085 -0.1 0" rpy="0 0 0"/>
    <child link="right_wheel"/>
    <parent link="chassis"/>
    <axis xyz="0 1 0" rpy="0 0 0"/>
    <limit effort="10000" velocity="1000"/>
    <dynamics damping="1.0" friction="1.0"/>
  </joint>

  <!-- camera -->
  <link name='camera'>
    <inertial>
    <mass value="0.1"/>
    <origin xyz="0 0 0" rpy=" 0 0 0"/>
    <inertia
        ixx="1e-6" ixy="0" ixz="0"
        iyy="1e-6" iyz="0"
        izz="1e-6"
    />
  </inertial>

  <collision name='camera_collision'>
    <origin xyz="0 0 0" rpy=" 0 0 0"/> 
    <geometry>
      <box size="0.04 0.04 0.04"/>
    </geometry>
  </collision>

  <visual name='camera_visual'>
    <origin xyz="0 0 0" rpy=" 0 0 0"/>
    <geometry>
      <box size="0.04 0.04 0.04"/>
    </geometry>
  </visual>
  </link>

  <joint type="fixed" name="camera_joint">
    <origin xyz="0.175 0 0" rpy="0 0 0"/>
    <child link="camera"/>
    <parent link="chassis"/>
    <axis xyz="0 1 0" rpy="0 0 0"/>
  </joint>

 <!-- hokuyo -->
 <link name='hokuyo'>
    <inertial>
    <mass value="1e-5"/>
    <origin xyz="0 0 0" rpy=" 0 0 0"/>
    <inertia
        ixx="1e-6" ixy="0" ixz="0"
        iyy="1e-6" iyz="0"
        izz="1e-6"
    />
  </inertial>

  <collision name='hokuyo_collision'>
    <origin xyz="0 0 0" rpy=" 0 0 0"/> 
    <geometry>
      <box size="0.1 0.1 0.1"/>
    </geometry>
  </collision>

  <visual name='hokuyo_visual'>
    <origin xyz="0 0 0" rpy=" 0 0 0"/>
    <geometry>
      <mesh filename="package://my_robot/meshes/hokuyo.dae"/>
    </geometry>
  </visual>
  </link>

  <joint type="fixed" name="hokuyo_joint">
    <origin xyz="-0.05 0 0.12" rpy="0 0 0"/>
    <child link="hokuyo"/>
    <parent link="chassis"/>
    <axis xyz="0 1 0" rpy="0 0 0"/>
  </joint>

  <!-- colors -->
  <gazebo reference="left_wheel">
    <material>Gazebo/Black</material>
  </gazebo>

  <gazebo reference="right_wheel">
    <material>Gazebo/Black</material>
 </gazebo>

  <gazebo reference="chassis">
    <material>Gazebo/Red</material>
 </gazebo>

  <gazebo reference="chassis_back">
    <material>Gazebo/Red</material>
  </gazebo>
  
  <gazebo reference="camera">
    <material>Gazebo/Blue</material>
 </gazebo>

  <gazebo reference="hokuyo">
    <material>Gazebo/Blue</material>
 </gazebo>



</robot>
